Workbook

Sheet Checklist
A1: GUI Checklist — Đăng ký (Registry) & Đăng nhập (Login)
A2: Hệ thống: EShop | URL test: https://eshop-sut-whje.vercel.app/
A3: Functional Requirements: FR-01 (Registry), FR-02 (Login)
A4: Ngày tạo checklist: 02/08/2026 | Ngày thực thi: 02/08/2026 | Trạng thái: Đã thực hiện
A6: STT | B6: Hạng mục kiểm tra | C6: IA | D6: Màn hình | E6: Pass/Fail | F6: Ghi chú (mô tả lỗi nếu Fail)
A7: 1 | B7: Tiêu đề/trang có nhãn rõ ràng (ví dụ: "Đăng ký", "Register") | C7: IA-01 | D7: Đăng ký | E7: Pass
A8: 2 | B8: Bố cục form căn chỉnh, khoảng cách giữa các trường đồng nhất | C8: IA-01 | D8: Đăng ký | E8: Pass
A9: 3 | B9: Font chữ, màu chữ dễ đọc trên nền hiện tại | C9: IA-01 | D9: Đăng ký | E9: Pass
A10: 4 | B10: Nhãn (label) hiển thị đầy đủ cho tất cả trường nhập | C10: IA-01 | D10: Đăng ký | E10: Pass
A11: 5 | B11: Trường bắt buộc được đánh dấu rõ (ví dụ: dấu * hoặc text "bắt buộc") | C11: IA-01 | D11: Đăng ký | E11: Pass
A12: 6 | B12: Nút submit có nhãn rõ ràng (ví dụ: "Đăng ký", "Register") | C12: IA-01 | D12: Đăng ký | E12: Pass
A13: 7 | B13: Giao diện responsive / hiển thị ổn trên viewport phổ biến | C13: IA-01 | D13: Đăng ký | E13: Pass
A14: 8 | B14: Trường Họ Tên hiển thị và cho phép nhập liệu | C14: IA-02 | D14: Đăng ký | E14: Pass
A15: 9 | B15: Trường Email hiển thị và cho phép nhập liệu | C15: IA-02 | D15: Đăng ký | E15: Pass
A16: 10 | B16: Trường Email dùng type="email" (validate HTML5 format) | C16: IA-02 | D16: Đăng ký | E16: Fail | F16: Email dùng `type="text"` thay vì `type="email"` — không có HTML5 format validation
A17: 11 | B17: Trường Mật khẩu hiển thị dạng che (password/masked) | C17: IA-02 | D17: Đăng ký | E17: Pass
A18: 12 | B18: Trường Xác nhận mật khẩu hiển thị và cho phép nhập liệu | C18: IA-02 | D18: Đăng ký | E18: Fail | F18: Không có trường Xác nhận mật khẩu — form chỉ có 1 password field
A19: 13 | B19: Submit khi để trống Họ Tên → hiển thị thông báo lỗi phù hợp | C19: IA-02 | D19: Đăng ký | E19: Pass
A20: 14 | B20: Submit khi để trống Email → hiển thị thông báo lỗi phù hợp | C20: IA-02 | D20: Đăng ký | E20: Pass
A21: 15 | B21: Submit khi để trống Mật khẩu → hiển thị thông báo lỗi phù hợp | C21: IA-02 | D21: Đăng ký | E21: Pass
A22: 16 | B22: Submit khi để trống Xác nhận mật khẩu → hiển thị thông báo lỗi phù hợp | C22: IA-02 | D22: Đăng ký | E22: Fail | F22: Không có trường Xác nhận mật khẩu để kiểm tra
A23: 17 | B23: Email sai định dạng (ví dụ: abc, user@) → bị từ chối với thông báo rõ ràng | C23: IA-02 | D23: Đăng ký | E23: Fail | F23: Email type="text" nên không có HTML5 format validation — "abc" được chấp nhận
A24: 18 | B24: Email đúng định dạng (user@domain.com) → pass validation format | C24: IA-02 | D24: Đăng ký | E24: Pass
A25: 19 | B25: Email đã tồn tại trong hệ thống → bị từ chối với thông báo phù hợp | C25: IA-02 | D25: Đăng ký | E25: Fail | F25: Không hiển thị thông báo lỗi trùng email — form vẫn ở trang /register
A26: 20 | B26: Mật khẩu < 8 ký tự → bị từ chối | C26: IA-02 | D26: Đăng ký | E26: Pass
A27: 21 | B27: Mật khẩu thiếu chữ hoa → bị từ chối | C27: IA-02 | D27: Đăng ký | E27: Pass
A28: 22 | B28: Mật khẩu thiếu chữ thường → bị từ chối | C28: IA-02 | D28: Đăng ký | E28: Pass
A29: 23 | B29: Mật khẩu thiếu chữ số → bị từ chối | C29: IA-02 | D29: Đăng ký | E29: Pass
A30: 24 | B30: Mật khẩu thiếu ký tự đặc biệt (@, $, !, %, *, ?, &) → bị từ chối | C30: IA-02 | D30: Đăng ký | E30: Pass
A31: 25 | B31: Mật khẩu đáp ứng đủ quy tắc mạnh → pass validation | C31: IA-02 | D31: Đăng ký | E31: Fail | F31: Đăng ký với mật khẩu mạnh không thành công — vẫn ở trang /register
A32: 26 | B32: Mật khẩu và Xác nhận mật khẩu không khớp → bị từ chối | C32: IA-02 | D32: Đăng ký | E32: Fail | F32: Không có trường Xác nhận mật khẩu để kiểm tra
A33: 27 | B33: Mật khẩu và Xác nhận mật khẩu khớp nhau → pass validation khớp | C33: IA-02 | D33: Đăng ký | E33: Fail | F33: Không có trường Xác nhận mật khẩu để kiểm tra
A34: 28 | B34: Có hướng dẫn/quy tắc mật khẩu hiển thị cho người dùng (nếu thiết kế có) | C34: IA-02 | D34: Đăng ký | E34: Pass
A35: 29 | B35: Tab order giữa các trường theo thứ tự logic (Họ Tên → Email → Mật khẩu → Xác nhận → Submit) | C35: IA-02 | D35: Đăng ký | E35: Pass
A36: 30 | B36: Có liên kết/chuyển hướng tới trang Đăng nhập (ví dụ: "Đã có tài khoản?") | C36: IA-03 | D36: Đăng ký | E36: Pass
A37: 31 | B37: Liên kết tới trang Đăng nhập hoạt động đúng | C37: IA-03 | D37: Đăng ký | E37: Pass
A38: 32 | B38: Đăng ký thành công → tự động chuyển hướng tới trang Đăng nhập | C38: IA-03 | D38: Đăng ký | E38: Pass
A39: 33 | B39: Trong lúc submit, nút Đăng ký bị vô hiệu hoặc hiển thị trạng thái loading | C39: IA-04 | D39: Đăng ký | E39: Fail | F39: Button không bị disabled và không có loading indicator
A40: 34 | B40: Lỗi validation hiển thị gần trường tương ứng hoặc vị trí dễ nhận biết | C40: IA-04 | D40: Đăng ký | E40: Pass
A41: 35 | B41: Thông báo lỗi dùng ngôn ngữ rõ ràng, không gây hiểu nhầm | C41: IA-04 | D41: Đăng ký | E41: Pass
...

Sheet Test Summary
A1: Tóm tắt kiểm thử (Test Summary)
A3: Số lượng màn hình đã kiểm thử | B3: =2 -> 2
A4: Số lượng hạng mục checklist đã thiết kế | B4: =COUNTA(Checklist!B7:B76) -> 70
A5: Số lượng hạng mục đã thực hiện (Pass+Fail+N/A) | B5: =COUNTIF(Checklist!E7:E76,"Pass")+COUNTIF(Checklist!E7:E76,"Fail")+COUNTIF(Checklist!E7:E76,"N/A") -> 70
A6: Số lượng hạng mục Pass | B6: =COUNTIF(Checklist!E7:E76,"Pass") -> 52
A7: Số lượng hạng mục Fail | B7: =COUNTIF(Checklist!E7:E76,"Fail") -> 18
A8: Số lượng lỗi được phát hiện (= số Fail) | B8: =COUNTIF(Checklist!E7:E76,"Fail") -> 18
A11: Phân bổ theo IA
A12: Nhóm IA | B12: Registry (FR-01) | C12: Login (FR-02) | D12: Tổng | E12: Pass | F12: Fail
A13: IA-01: General UI Standards | B13: =COUNTIFS(Checklist!C7:C76,"IA-01",Checklist!D7:D76,"Đăng ký") -> 10 | C13: =COUNTIFS(Checklist!C7:C76,"IA-01",Checklist!D7:D76,"Đăng nhập") -> 9 | D13: =COUNTIF(Checklist!C7:C76,"IA-01") -> 19 | E13: =COUNTIFS(Checklist!C7:C76,"IA-01",Checklist!E7:E76,"Pass") -> 18 | F13: =COUNTIFS(Checklist!C7:C76,"IA-01",Checklist!E7:E76,"Fail") -> 1
A14: IA-02: Forms | B14: =COUNTIFS(Checklist!C7:C76,"IA-02",Checklist!D7:D76,"Đăng ký") -> 22 | C14: =COUNTIFS(Checklist!C7:C76,"IA-02",Checklist!D7:D76,"Đăng nhập") -> 8 | D14: =COUNTIF(Checklist!C7:C76,"IA-02") -> 30 | E14: =COUNTIFS(Checklist!C7:C76,"IA-02",Checklist!E7:E76,"Pass") -> 19 | F14: =COUNTIFS(Checklist!C7:C76,"IA-02",Checklist!E7:E76,"Fail") -> 11
A15: IA-03: Navigation | B15: =COUNTIFS(Checklist!C7:C76,"IA-03",Checklist!D7:D76,"Đăng ký") -> 3 | C15: =COUNTIFS(Checklist!C7:C76,"IA-03",Checklist!D7:D76,"Đăng nhập") -> 3 | D15: =COUNTIF(Checklist!C7:C76,"IA-03") -> 6 | E15: =COUNTIFS(Checklist!C7:C76,"IA-03",Checklist!E7:E76,"Pass") -> 6 | F15: =COUNTIFS(Checklist!C7:C76,"IA-03",Checklist!E7:E76,"Fail") -> 0
A16: IA-04: Feedback/State | B16: =COUNTIFS(Checklist!C7:C76,"IA-04",Checklist!D7:D76,"Đăng ký") -> 5 | C16: =COUNTIFS(Checklist!C7:C76,"IA-04",Checklist!D7:D76,"Đăng nhập") -> 10 | D16: =COUNTIF(Checklist!C7:C76,"IA-04") -> 15 | E16: =COUNTIFS(Checklist!C7:C76,"IA-04",Checklist!E7:E76,"Pass") -> 9 | F16: =COUNTIFS(Checklist!C7:C76,"IA-04",Checklist!E7:E76,"Fail") -> 6
A17: Tổng | B17: =SUM(B13:B16) -> 40 | C17: =SUM(C13:C16) -> 30 | D17: =SUM(D13:D16) -> 70 | E17: =SUM(E13:E16) -> 52 | F17: =SUM(F13:F16) -> 18

Sheet Bug List
A1: Danh sách lỗi phát hiện (Bugs Found) — EShop Registry & Login
A3: Bug ID | B3: Mô tả | C3: Severity | D3: Checklist STT | E3: GitHub Issue #
A4: BUG-01 | B4: Register: Email field dùng type="text" thay vì type="email" — không có HTML5 format validation | C4: Major | D4: 10, 17 | E4: #81
A5: BUG-02 | B5: Register: Không có trường Xác nhận mật khẩu (Confirm Password) | C5: Critical | D5: 12, 16, 26, 27 | E5: #82
A6: BUG-03 | B6: Register: Button submit không có disabled/loading state trong lúc gửi | C6: Major | D6: 33 | E6: #83
A7: BUG-04 | B7: Register: Email trùng không hiển thị lỗi rõ ràng | C7: Major | D7: 19 | E7: #84
A8: BUG-05 | B8: Register: Đăng ký thành công không có phản hồi rõ (toast/message) | C8: Major | D8: 36 | E8: #85
A9: BUG-06 | B9: Login: Heading trang Login hiển thị "Đăng Ký" thay vì "Đăng Nhập" | C9: Major | D9: 41 | E9: #86
A10: BUG-07 | B10: Login: Username field dùng type="text" thay vì type="email" — không có HTML5 validation | C10: Major | D10: 48, 52 | E10: #87
A11: BUG-08 | B11: Login: Mật khẩu dùng type="text" — hiển thị PLAINTEXT, không che | C11: Critical | D11: 49 | E11: #88
A12: BUG-09 | B12: Login: Không có thông báo khóa tài khoản sau 3 lần sai | C12: Critical | D12: 60, 61, 65 | E12: #89
A13: BUG-10 | B13: Login: Button submit không có disabled/loading state trong lúc gửi | C13: Major | D13: 66 | E13: #90
A15: Tổng: 10 bugs
A16: Critical: 3 | Major: 7
